Workbook

Sheet README
B2: 먹괴음 QA 테스트 케이스
B3: 작성일: 2026-09-07 | 버전: v1.1 | 대상 빌드: 2026-09-07 EnemyBase/asmdef/네임스페이스 리팩토링 이후
B5: 시트 구성
B6: README | C6: 이 문서 사용법
B7: Summary | C7: 카테고리/우선순위별 집계 + 진행률 대시보드
B8: TestCases | C8: 실제 테스트 케이스 60건
B10: 컬럼 설명
B11: TC ID | C11: 모듈코드-일련번호. 예를 들어 TC-CBT-001. 버그 리포트나 커밋에서 이 ID로 케이스를 참조하세요.
B12: 모듈/기능 | C12: 테스트 대상 시스템과 세부 기능
B13: 유형 | C13: 기능은 정상 동작 확인, 회귀는 과거 버그 재발 방지, 경계값은 한계치 검증, 예외처리는 비정상 입력 대응
B14: 테스트 케이스 | C14: 무엇을 검증하는지 한 줄 요약
B15: 사전조건 / 테스트 데이터 | C15: 테스트 시작 전 상태, 사용할 구체적인 수치·입력값
B16: 테스트 절차 / 예상 결과 | C16: 수행 순서와 정상 기준
B17: 우선순위 | C17: P0는 핵심 플레이 루프라 반드시 확인, P1은 중요, P2는 부가 기능
B18: 자동화 | C18: Y는 Unity Test Framework EditMode 테스트로 이미 커버됨, N은 수동 테스트 필요
B19: 실제 결과 / 결과 / 테스터 / 테스트일자 / 빌드-버전 / 결함ID | C19: 테스트 실행 시 QA가 직접 채우는 칸. 결과는 Pass, Fail, Blocked, N-A 중 하나로 기록
B20: 비고 | C20: 관련 과거 버그, 참고 문서, 특이사항
B22: 결과 색상 규칙 — TestCases 시트 '결과' 컬럼
B23: Pass | C23: 정상 통과
B24: Fail | C24: 실패 — 결함ID에 이슈 트래커 번호 기록
B25: Blocked | C25: 선행 조건/환경 문제로 테스트 불가
B26: N/A | C26: 해당 없음, 이번 빌드에서 테스트 대상 아님

Sheet Summary
B2: 테스트 진행 현황 대시보드
B3: TestCases 시트의 '결과' 컬럼을 채우면 아래 집계가 자동으로 갱신됩니다.
B5: 총 테스트 케이스 | C5: 60
B6: Pass | C6: =COUNTIF(TestCases!M:M,"Pass")
B7: Fail | C7: =COUNTIF(TestCases!M:M,"Fail")
B8: Blocked | C8: =COUNTIF(TestCases!M:M,"Blocked")
B9: 미실행 | C9: =60-COUNTA(TestCases!M2:M61)
B10: 진행률 | C10: =COUNTA(TestCases!M2:M61)/60
B13: 모듈 | C13: 케이스 수 | D13: P0 | E13: P1 | F13: P2 | G13: 회귀 케이스
B14: 전투-기본공격 | C14: =COUNTIF(TestCases!B:B,"전투-기본공격") | D14: =COUNTIFS(TestCases!B:B,"전투-기본공격",TestCases!J:J,"P0") | E14: =COUNTIFS(TestCases!B:B,"전투-기본공격",TestCases!J:J,"P1") | F14: =COUNTIFS(TestCases!B:B,"전투-기본공격",TestCases!J:J,"P2") | G14: =COUNTIFS(TestCases!B:B,"전투-기본공격",TestCases!D:D,"회귀")
B15: 전투-색스킬 | C15: =COUNTIF(TestCases!B:B,"전투-색스킬") | D15: =COUNTIFS(TestCases!B:B,"전투-색스킬",TestCases!J:J,"P0") | E15: =COUNTIFS(TestCases!B:B,"전투-색스킬",TestCases!J:J,"P1") | F15: =COUNTIFS(TestCases!B:B,"전투-색스킬",TestCases!J:J,"P2") | G15: =COUNTIFS(TestCases!B:B,"전투-색스킬",TestCases!D:D,"회귀")
B16: 전투-회피 | C16: =COUNTIF(TestCases!B:B,"전투-회피") | D16: =COUNTIFS(TestCases!B:B,"전투-회피",TestCases!J:J,"P0") | E16: =COUNTIFS(TestCases!B:B,"전투-회피",TestCases!J:J,"P1") | F16: =COUNTIFS(TestCases!B:B,"전투-회피",TestCases!J:J,"P2") | G16: =COUNTIFS(TestCases!B:B,"전투-회피",TestCases!D:D,"회귀")
B17: 전투-락온 | C17: =COUNTIF(TestCases!B:B,"전투-락온") | D17: =COUNTIFS(TestCases!B:B,"전투-락온",TestCases!J:J,"P0") | E17: =COUNTIFS(TestCases!B:B,"전투-락온",TestCases!J:J,"P1") | F17: =COUNTIFS(TestCases!B:B,"전투-락온",TestCases!J:J,"P2") | G17: =COUNTIFS(TestCases!B:B,"전투-락온",TestCases!D:D,"회귀")
B18: 몹AI-평 | C18: =COUNTIF(TestCases!B:B,"몹AI-평") | D18: =COUNTIFS(TestCases!B:B,"몹AI-평",TestCases!J:J,"P0") | E18: =COUNTIFS(TestCases!B:B,"몹AI-평",TestCases!J:J,"P1") | F18: =COUNTIFS(TestCases!B:B,"몹AI-평",TestCases!J:J,"P2") | G18: =COUNTIFS(TestCases!B:B,"몹AI-평",TestCases!D:D,"회귀")
B19: 몹AI-원 | C19: =COUNTIF(TestCases!B:B,"몹AI-원") | D19: =COUNTIFS(TestCases!B:B,"몹AI-원",TestCases!J:J,"P0") | E19: =COUNTIFS(TestCases!B:B,"몹AI-원",TestCases!J:J,"P1") | F19: =COUNTIFS(TestCases!B:B,"몹AI-원",TestCases!J:J,"P2") | G19: =COUNTIFS(TestCases!B:B,"몹AI-원",TestCases!D:D,"회귀")
B20: 몹AI-흡 | C20: =COUNTIF(TestCases!B:B,"몹AI-흡") | D20: =COUNTIFS(TestCases!B:B,"몹AI-흡",TestCases!J:J,"P0") | E20: =COUNTIFS(TestCases!B:B,"몹AI-흡",TestCases!J:J,"P1") | F20: =COUNTIFS(TestCases!B:B,"몹AI-흡",TestCases!J:J,"P2") | G20: =COUNTIFS(TestCases!B:B,"몹AI-흡",TestCases!D:D,"회귀")
B21: 몹AI-분 | C21: =COUNTIF(TestCases!B:B,"몹AI-분") | D21: =COUNTIFS(TestCases!B:B,"몹AI-분",TestCases!J:J,"P0") | E21: =COUNTIFS(TestCases!B:B,"몹AI-분",TestCases!J:J,"P1") | F21: =COUNTIFS(TestCases!B:B,"몹AI-분",TestCases!J:J,"P2") | G21: =COUNTIFS(TestCases!B:B,"몹AI-분",TestCases!D:D,"회귀")
B22: 몹AI-광 | C22: =COUNTIF(TestCases!B:B,"몹AI-광") | D22: =COUNTIFS(TestCases!B:B,"몹AI-광",TestCases!J:J,"P0") | E22: =COUNTIFS(TestCases!B:B,"몹AI-광",TestCases!J:J,"P1") | F22: =COUNTIFS(TestCases!B:B,"몹AI-광",TestCases!J:J,"P2") | G22: =COUNTIFS(TestCases!B:B,"몹AI-광",TestCases!D:D,"회귀")
B23: 몹AI-공통 | C23: =COUNTIF(TestCases!B:B,"몹AI-공통") | D23: =COUNTIFS(TestCases!B:B,"몹AI-공통",TestCases!J:J,"P0") | E23: =COUNTIFS(TestCases!B:B,"몹AI-공통",TestCases!J:J,"P1") | F23: =COUNTIFS(TestCases!B:B,"몹AI-공통",TestCases!J:J,"P2") | G23: =COUNTIFS(TestCases!B:B,"몹AI-공통",TestCases!D:D,"회귀")
B24: 보스전 | C24: =COUNTIF(TestCases!B:B,"보스전") | D24: =COUNTIFS(TestCases!B:B,"보스전",TestCases!J:J,"P0") | E24: =COUNTIFS(TestCases!B:B,"보스전",TestCases!J:J,"P1") | F24: =COUNTIFS(TestCases!B:B,"보스전",TestCases!J:J,"P2") | G24: =COUNTIFS(TestCases!B:B,"보스전",TestCases!D:D,"회귀")
B25: 색구슬시스템 | C25: =COUNTIF(TestCases!B:B,"색구슬시스템") | D25: =COUNTIFS(TestCases!B:B,"색구슬시스템",TestCases!J:J,"P0") | E25: =COUNTIFS(TestCases!B:B,"색구슬시스템",TestCases!J:J,"P1") | F25: =COUNTIFS(TestCases!B:B,"색구슬시스템",TestCases!J:J,"P2") | G25: =COUNTIFS(TestCases!B:B,"색구슬시스템",TestCases!D:D,"회귀")
B26: 색칠/복원 | C26: =COUNTIF(TestCases!B:B,"색칠/복원") | D26: =COUNTIFS(TestCases!B:B,"색칠/복원",TestCases!J:J,"P0") | E26: =COUNTIFS(TestCases!B:B,"색칠/복원",TestCases!J:J,"P1") | F26: =COUNTIFS(TestCases!B:B,"색칠/복원",TestCases!J:J,"P2") | G26: =COUNTIFS(TestCases!B:B,"색칠/복원",TestCases!D:D,"회귀")
B27: 룸클리어/계단 | C27: =COUNTIF(TestCases!B:B,"룸클리어/계단") | D27: =COUNTIFS(TestCases!B:B,"룸클리어/계단",TestCases!J:J,"P0") | E27: =COUNTIFS(TestCases!B:B,"룸클리어/계단",TestCases!J:J,"P1") | F27: =COUNTIFS(TestCases!B:B,"룸클리어/계단",TestCases!J:J,"P2") | G27: =COUNTIFS(TestCases!B:B,"룸클리어/계단",TestCases!D:D,"회귀")
B28: 세이브/로드 | C28: =COUNTIF(TestCases!B:B,"세이브/로드") | D28: =COUNTIFS(TestCases!B:B,"세이브/로드",TestCases!J:J,"P0") | E28: =COUNTIFS(TestCases!B:B,"세이브/로드",TestCases!J:J,"P1") | F28: =COUNTIFS(TestCases!B:B,"세이브/로드",TestCases!J:J,"P2") | G28: =COUNTIFS(TestCases!B:B,"세이브/로드",TestCases!D:D,"회귀")
B29: 게임오버/리트라이 | C29: =COUNTIF(TestCases!B:B,"게임오버/리트라이") | D29: =COUNTIFS(TestCases!B:B,"게임오버/리트라이",TestCases!J:J,"P0") | E29: =COUNTIFS(TestCases!B:B,"게임오버/리트라이",TestCases!J:J,"P1") | F29: =COUNTIFS(TestCases!B:B,"게임오버/리트라이",TestCases!J:J,"P2") | G29: =COUNTIFS(TestCases!B:B,"게임오버/리트라이",TestCases!D:D,"회귀")
B30: UI | C30: =COUNTIF(TestCases!B:B,"UI") | D30: =COUNTIFS(TestCases!B:B,"UI",TestCases!J:J,"P0") | E30: =COUNTIFS(TestCases!B:B,"UI",TestCases!J:J,"P1") | F30: =COUNTIFS(TestCases!B:B,"UI",TestCases!J:J,"P2") | G30: =COUNTIFS(TestCases!B:B,"UI",TestCases!D:D,"회귀")
B31: 리팩토링검증 | C31: =COUNTIF(TestCases!B:B,"리팩토링검증") | D31: =COUNTIFS(TestCases!B:B,"리팩토링검증",TestCases!J:J,"P0") | E31: =COUNTIFS(TestCases!B:B,"리팩토링검증",TestCases!J:J,"P1") | F31: =COUNTIFS(TestCases!B:B,"리팩토링검증",TestCases!J:J,"P2") | G31: =COUNTIFS(TestCases!B:B,"리팩토링검증",TestCases!D:D,"회귀")
B32: 자동화 단위테스트 | C32: =COUNTIF(TestCases!B:B,"자동화 단위테스트") | D32: =COUNTIFS(TestCases!B:B,"자동화 단위테스트",TestCases!J:J,"P0") | E32: =COUNTIFS(TestCases!B:B,"자동화 단위테스트",TestCases!J:J,"P1") | F32: =COUNTIFS(TestCases!B:B,"자동화 단위테스트",TestCases!J:J,"P2") | G32: =COUNTIFS(TestCases!B:B,"자동화 단위테스트",TestCases!D:D,"회귀")

Sheet TestCases
A1: TC ID | B1: 모듈 | C1: 기능 | D1: 유형 | E1: 테스트 케이스 | F1: 사전조건 | G1: 테스트 데이터 | H1: 테스트 절차 | I1: 예상 결과 | J1: 우선순위 | K1: 자동화 | L1: 실제 결과 | M1: 결과 | N1: 테스터 | O1: 테스트일자 | P1: 빌드/버전 | Q1: 결함ID | R1: 비고
A2: TC-CBT-001 | B2: 전투-기본공격 | C2: 붓 3타 콤보 | D2: 기능 | E2: 콤보가 순서대로 진행된다 | F2: 적 1마리 근접 | G2: - | H2: Recovery 구간 마지막 6프레임인 입력 버퍼 안에서 좌클릭을 3번 연타 | I2: 1타→2타→3타 순서로 이어지고, 대미지가 각각 attackPower×0.6/0.7/1.0으로 커진다 | J2: P0 | K2: N
A3: TC-CBT-002 | B3: 전투-기본공격 | C3: 붓 3타 콤보 | D3: 경계값 | E3: 버퍼 구간을 놓치면 콤보가 끊긴다 | F3: 적 1마리 근접 | G3: - | H3: 1타 명중 후 Recovery 버퍼 구간이 지나도록 기다렸다가 다시 클릭 | I3: 콤보가 1타로 리셋되고 새 콤보가 시작된다, 2타로는 안 이어짐 | J3: P1 | K3: N
A4: TC-CBT-003 | B4: 전투-기본공격 | C4: 붓 3타 콤보 | D4: 회귀 | E4: 자기 자신은 맞지 않는다 | F4: 적 근접 | G4: attackPower=1000, 즉사 확인용 | H4: 공격력을 임시로 크게 올린 뒤 공격을 여러 번 반복 | I4: 플레이어 자신의 HP/피격 로그가 발생하지 않는다 | J4: P0 | K4: N | R4: 2026-08-21 CharacterController 자기 타격 버그
A5: TC-CBT-004 | B5: 전투-기본공격 | C5: 붓 3타 콤보 | D5: 기능 | E5: 히트스탑 연출이 걸린다 | F5: 적 근접, 명중 확정 | G5: - | H5: 공격해서 명중시킨다 | I5: 명중 순간 약 0.05초 Time.timeScale=0으로 잠깐 멈췄다가 정상 복귀한다 | J5: P2 | K5: N
A6: TC-SKL-001 | B6: 전투-색스킬 | C6: 빨강 강타 | D6: 기능 | E6: 구슬 보유 시 정상 발동 | F6: 빨강 구슬 1개 이상, 쿨타임 아님 | G6: 키 입력=1 | H6: 키 1 입력 | I6: 구슬 1개 소모, Startup 대기 후 전방 대시+강타 판정 발생 | J6: P0 | K6: N
A7: TC-SKL-002 | B7: 전투-색스킬 | C7: 빨강 강타 | D7: 예외처리 | E7: 구슬 없으면 발동 안 함 | F7: 빨강 구슬 0개 | G7: 키 입력=1 | H7: 키 1 입력 | I7: 스킬이 나가지 않고 '구슬이 없어서 스킬을 쓸 수 없음' 로그만 뜬다 | J7: P1 | K7: N
A8: TC-SKL-003 | B8: 전투-색스킬 | C8: 빨강 강타 | D8: 경계값 | E8: 쿨타임 중 재입력 무시 | F8: 직전에 강타 사용, 8초 이내 | G8: 경과시간<8s | H8: 키 1 재입력 | I8: 스킬이 발동하지 않고 구슬도 소모되지 않는다 | J8: P1 | K8: N
A9: TC-SKL-004 | B9: 전투-색스킬 | C9: 파랑 흐름 | D9: 기능 | E9: 직선 관통으로 다중 적 타격 | F9: 적 여러 마리를 일렬로 배치 | G9: 파랑 구슬≥1 | H9: 파랑 구슬 보유 후 키 2 | I9: 일직선 박스 범위 안의 적 전부가 동시에 피해를 입는다 | J9: P1 | K9: N
A10: TC-SKL-005 | B10: 전투-색스킬 | C10: 노랑 번쩍 | D10: 기능 | E10: 범위 피해 + 넉백 | F10: 적 여러 마리가 주변에 있음 | G10: 노랑 구슬≥1 | H10: 노랑 구슬 보유 후 키 3 | I10: 반경 내 적 전부 피해와 넉백을 받고, 플레이어 자신은 제외된다 | J10: P1 | K10: N
A11: TC-SKL-006 | B11: 전투-색스킬 | C11: 조준 보정 | D11: 회귀 | E11: 락온 중이면 스킬이 타겟 방향으로 나간다 | F11: 적을 Tab으로 락온한 상태 | G11: - | H11: 락온 유지한 채 강타/흐름 시전 | I11: transform.forward가 아니라 락온 타겟 방향으로 판정 중심이 잡힌다 | J11: P1 | K11: N | R11: 2026-09-02 스킬이 허공을 치는 버그
A12: TC-DGE-001 | B12: 전투-회피 | C12: 구르기 Space | D12: 경계값 | E12: 무적프레임 구간에서만 무적 | F12: 구르기 가능 상태 | G12: 0~3f/15~24f 구간 피격 유도 | H12: 구르기 시작 직후 Startup 0~3프레임과 Recovery 15~24프레임 구간에 피격 유도 | I12: 이 구간에서는 데미지를 입는다, 무적은 3~15프레임 i-frame 구간에서만 적용된다 | J12: P0 | K12: N
A13: TC-DGE-002 | B13: 전투-회피 | C13: 구르기 Space | D13: 경계값 | E13: 쿨타임 1초 적용 | F13: 직전 구르기 종료 직후 | G13: 경과<1s | H13: 1초 이내에 다시 Space 입력 | I13: 구르기가 발동하지 않는다 | J13: P1 | K13: N
A14: TC-DGE-003 | B14: 전투-회피 | C14: 구르기 Space | D14: 기능 | E14: 구르는 동안 주변 적을 밀어낸다 | F14: 흡 EnemyHeup이 회복 구역으로 도주 중 | G14: - | H14: 흡을 스치도록 구르기 | I14: 흡이 넉백되어 도주 경로가 저지된다 | J14: P1 | K14: N | R14: QA 리뷰 SYS-4 대응 기능
A15: TC-LOC-001 | B15: 전투-락온 | C15: Tab 락온 | D15: 기능 | E15: 가장 가까운 적을 락온한다 | F15: 반경 lockOnRadius 내 적 2마리 이상 | G15: - | H15: Tab 입력 | I15: 가장 가까운 적이 락온되고 화면에 마커가 뜬다 | J15: P1 | K15: N
A16: TC-LOC-002 | B16: 전투-락온 | C16: Tab 락온 | D16: 기능 | E16: 재입력 시 다른 타겟으로 순환 | F16: 이미 한 적을 락온 중, 근처에 다른 적도 있음 | G16: 쿨다운 10f 경과 | H16: 쿨다운 지난 뒤 Tab 재입력 | I16: 락온 대상이 다음 후보로 바뀐다 | J16: P2 | K16: N
A17: TC-LOC-003 | B17: 전투-락온 | C17: Tab 락온 | D17: 기능 | E17: 타겟 사망 시 자동 해제 | F17: 적을 락온한 상태 | G17: - | H17: 락온 대상을 처치 | I17: 락온이 자동으로 풀리고 마커가 사라진다 | J17: P1 | K17: N
A18: TC-LOC-004 | B18: 전투-락온 | C18: Tab 락온 | D18: 예외처리 | E18: 죽은 보스는 락온되지 않는다 | F18: 보스를 처치해서 IsDead=true, 오브젝트는 남아있음 | G18: - | H18: Tab으로 재탐색 | I18: 죽은 보스가 후보에서 제외된다 | J18: P1 | K18: N
A19: TC-AIP-001 | B19: 몹AI-평 | C19: 추격/공격 | D19: 기능 | E19: 시야 진입 시 추격, 사거리 진입 시 공격 | F19: 평 1마리, 플레이어가 sightRadius 밖에서 접근 | G19: - | H19: 플레이어가 시야→사거리 순으로 진입 | I19: 추격 시작 → 사거리 도달 시 Windup, 피해가 발생하는 Active, Recovery 순으로 진행 | J19: P0 | K19: N
A20: TC-AIP-002 | B20: 몹AI-평 | C20: 넉백 | D20: 기능 | E20: 넉백 종료 후 공격 상태 리셋 | F20: 평이 공격 Windup/Active 중 | G20: - | H20: 그 순간 넉백 적용 | I20: 넉백 종료 후 Chase/Idle 상태로 돌아가며 이전 공격이 이어지지 않는다 | J20: P1 | K20: N
A21: TC-AIW-001 | B21: 몹AI-원 | C21: 사거리 유지 | D21: 기능 | E21: 사거리 2~5m 안이면 투척, 너무 가까우면 후퇴 | F21: 원 1마리, 플레이어 접근 | G21: - | H21: 플레이어가 원에게 점점 다가간다 | I21: 5m 이내 진입 시 투척 시작, 1.5m 이내로 붙으면 후퇴로 전환 | J21: P0 | K21: N
A22: TC-AIW-002 | B22: 몹AI-원 | C22: 투사체 | D22: 기능 | E22: 먹물 투사체 명중 시 피해 | F22: 원이 투척 상태 | G22: - | H22: 투사체가 플레이어에 명중 | I22: 플레이어 HP가 attackPower만큼 감소 | J22: P1 | K22: N
A23: TC-AIH-001 | B23: 몹AI-흡 | C23: 회복 행동 | D23: 기능 | E23: HP 50% 밑에서 회복구역으로 이동 후 흡수 | F23: 흡 HP를 50% 밑으로 감소 | G23: lowHpThreshold=0.5 | H23: 행동 관찰 | I23: 가장 가까운 색 복원 구역으로 이동, 도달하면 초당 healPerSecond로 회복 | J23: P0 | K23: N
A24: TC-AIH-002 | B24: 몹AI-흡 | C24: 회복 히스테리시스 | D24: 회귀 | E24: 회복 시작 후 100% 찰 때까지 멈추지 않는다 | F24: 흡이 회복 중, HP가 50% 살짝 넘김 | G24: - | H24: 회복 지속 관찰 | I24: 50%를 넘어도 회복을 멈추지 않고 100%까지 계속한다 | J24: P1 | K24: N | R24: 2026-08-20 '왜 절반까지만 회복하냐' 피드백 대응
A25: TC-AIH-003 | B25: 몹AI-흡 | C25: 비공격 확인 | D25: 기능 | E25: 흡은 플레이어를 절대 공격하지 않는다 | F25: 흡과 플레이어가 근접 | G25: - | H25: 장시간 관찰 | I25: HP 상태와 무관하게 공격 판정이 한 번도 발생하지 않는다 | J25: P1 | K25: N
A26: TC-AIB-001 | B26: 몹AI-분 | C26: 분열 | D26: 기능 | E26: 사망 시 미니언 2마리로 분열 | F26: 분열 전 원본 1마리 | G26: - | H26: 분을 처치 | I26: 체력 50%·크기 60%인 미니언 2마리가 근처에 생성된다 | J26: P0 | K26: N
A27: TC-AIB-002 | B27: 몹AI-분 | C27: 분열 | D27: 경계값 | E27: 미니언은 재분열하지 않는다 | F27: 분열로 생성된 미니언 | G27: isMinor=true | H27: 미니언을 처치 | I27: 추가 미니언이 생성되지 않아 무한 분열을 방지한다 | J27: P1 | K27: N
A28: TC-AIG-001 | B28: 몹AI-광 | C28: 쿨다운 공격 | D28: 기능 | E28: 쿨다운이 차면 사거리 무관 AOE 공격 | F28: 광 1마리, 플레이어 시야 안 | G28: - | H28: 쿨다운 도달까지 대기 | I28: 그 자리에 멈춰 경고 인디케이터 표시 후 AOE 피해 발생 | J28: P0 | K28: N
A29: TC-AIG-002 | B29: 몹AI-광 | C29: 넉백 취소 | D29: 기능 | E29: 공격 준비 중 넉백당하면 경고 인디케이터도 같이 사라진다 | F29: 광이 AOE Windup 중이라 경고 인디케이터가 표시된 상태 | G29: - | H29: 그 순간 넉백 적용 | I29: 경고 인디케이터가 즉시 사라지고 공격이 취소된다 | J29: P2 | K29: N
A30: TC-AIC-001 | B30: 몹AI-공통 | C30: 넉백 EnemyBase | D30: 기능 | E30: 넉백 중에는 AI 로직이 정지한다 | F30: 임의의 몹 1종 | G30: - | H30: 넉백 적용 | I30: 넉백 지속 시간 0.25초 동안 추격/공격 로직이 멈추고 물리적으로만 밀려난다 | J30: P0 | K30: N | R30: EnemyBase 리팩토링 2026-09-07 검증 항목
A31: TC-AIC-002 | B31: 몹AI-공통 | C31: 넉백 EnemyBase | D31: 기능 | E31: 넉백 종료 후 NavMesh 위로 복귀 | F31: 몹이 NavMeshAgent로 이동 중, 넉백 적용 | G31: - | H31: 넉백 종료 관찰 | I31: agent가 다시 활성화되고 NavMesh 위 유효한 위치로 재동기화되어, 허공에 뜨거나 밀리는 문제가 없다 | J31: P1 | K31: N
A32: TC-BOSS-001 | B32: 보스전 | C32: 공격 패턴 | D32: 기능 | E32: 1페이즈 6종 공격이 전부 정상 동작 | F32: 보스룸, 1페이즈 | G32: - | H32: 장시간 교전하며 강타/흐름/번쩍/되살림/왜곡/먹물 전부 유도 | I32: 6종 공격 각각 텔레그래프→판정이 기획대로 나간다 | J32: P0 | K32: N
A33: TC-BOSS-002 | B33: 보스전 | C33: 페이즈 전환 | D33: 기능 | E33: HP 50% 밑에서 2페이즈 전환 + 무적 위치교란 | F33: 보스 HP를 50% 밑으로 감소 | G33: phase2Threshold=0.5 | H33: 전환 순간 관찰 | I33: 즉시 무적 상태가 되어 위치교란 순간이동을 강제 시전하고, 끝나면 무적 해제 | J33: P0 | K33: N
A34: TC-BOSS-003 | B34: 보스전 | C34: 위치교란 | D34: 회귀 | E34: 위치교란 후 보스가 방 밖으로 나가지 않는다 | F34: 2페이즈, 위치교란 유도 | G34: displaceRadius=8, 방 half-extent=4.3 | H34: 여러 번 반복 시전 | I34: 이동 결과 좌표가 항상 방 안전 범위인 ±4.3m 안으로 clamp된다 | J34: P0 | K34: N | R34: 2026-09-02 '보스가 맵 밖으로 떨어짐' 버그
A35: TC-BOSS-004 | B35: 보스전 | C35: 사망 처리 | D35: 회귀 | E35: 보스 사망 시 진행 중이던 공격이 취소된다 | F35: 보스가 공격 Windup 대기 중 | G35: - | H35: 그 프레임에 킬샷을 넣음 | I35: 죽은 뒤에는 왜곡 등 진행 중이던 공격이 발동되지 않는다 | J35: P0 | K35: N | R35: 2026-09-04 '죽은 보스가 스킬을 씀' 버그
A36: TC-BOSS-005 | B36: 보스전 | C36: 넉백 면역 | D36: 기능 | E36: 보스는 넉백당하지 않는다 | F36: 노랑 번쩍이나 구르기 등 넉백 수단 보유 | G36: - | H36: 보스에게 넉백 시도 | I36: 보스 위치가 전혀 밀리지 않는다, IKnockbackable 미구현 | J36: P2 | K36: N
A37: TC-ORB-001 | B37: 색구슬시스템 | C37: 보유 상한 | D37: 경계값 | E37: 5개 초과 시 가장 오래된 색부터 FIFO로 빠진다 | F37: 서로 다른 색 구슬 5개 보유 | G37: maxHeldOrbs=5 | H37: 새로운 색의 6번째 구슬 획득 | I37: 가장 먼저 얻은 색이 1개 줄고 새 색이 추가되어 합계 5개 유지 | J37: P1 | K37: N
A38: TC-ORB-002 | B38: 색구슬시스템 | C38: 스킬 소모 | D38: 예외처리 | E38: 스킬 사용 후에도 FIFO 순서 정합성 유지 | F38: 여러 색 구슬 보유 | G38: - | H38: 스킬로 특정 색 소모 후 구슬을 계속 획득/소모 반복 | I38: heldOrbs와 내부 소모 순서가 어긋나 음수/예외가 발생하지 않는다 | J38: P2 | K38: N
A39: TC-ORB-003 | B39: 색구슬시스템 | C39: 누적 기록 | D39: 기능 | E39: Lifetime 카운트는 절대 감소하지 않는다 | F39: 구슬 여러 개 획득 후 스킬로 소모 | G39: - | H39: 소모 후 보유/누적 비교 | I39: 보유 Held는 줄어도 누적 Lifetime 값은 그대로거나 계속 증가만 한다 | J39: P2 | K39: N
A40: TC-PNT-001 | B40: 색칠/복원 | C40: 색 복원 파동 | D40: 기능 | E40: 파동이 닿으면 서서히 원색으로 복귀 | F40: 회색 상태의 PaintableObject | G40: fadeDuration=0.2s | H40: 색 복원 파동으로 Paint() 트리거 | I40: fadeDuration에 걸쳐 자연스럽게 원래 색으로 보간된다 | J40: P1 | K40: N
...
